ryukomura_laptop@MacBook-Pro-2 codes % python video.py
/Users/ryukomura_laptop/Library/Mobile Documents/com~apple~CloudDocs/programming/TrafficSignRecognition/codes
/Users/ryukomura_laptop/Library/Mobile Documents/com~apple~CloudDocs/programming/TrafficSignRecognition
<_io.TextIOWrapper name='/Users/ryukomura_laptop/Library/Mobile Documents/com~apple~CloudDocs/programming/TrafficSignRecognition/keys.json' mode='r' encoding='UTF-8'>
Changed waitThread to realtime priority!
Asked for all format descriptions...
2022-01-13 10:17:20.481152: I tensorflow/core/platform/cpu_feature_guard.cc:142] This TensorFlow binary is optimized with oneAPI Deep Neural Network Library (oneDNN) to use the following CPU instructions in performance-critical operations:  AVX2 FMA
To enable them in other operations, rebuild TensorFlow with the appropriate compiler flags.
2022-01-13 10:17:20.827105: I tensorflow/compiler/mlir/mlir_graph_optimization_pass.cc:176] None of the MLIR Optimization Passes are enabled (registered 2)
Traceback (most recent call last):
  File "/Users/ryukomura_laptop/Library/Mobile Documents/com~apple~CloudDocs/programming/TrafficSignRecognition/codes/video.py", line 84, in <module>
    predictions = model.predict(img)
  File "/Users/ryukomura_laptop/.pyenv/versions/3.9.5/lib/python3.9/site-packages/keras/engine/training.py", line 1702, in predict
    tmp_batch_outputs = self.predict_function(iterator)
  File "/Users/ryukomura_laptop/.pyenv/versions/3.9.5/lib/python3.9/site-packages/tensorflow/python/eager/def_function.py", line 889, in __call__
    result = self._call(*args, **kwds)
  File "/Users/ryukomura_laptop/.pyenv/versions/3.9.5/lib/python3.9/site-packages/tensorflow/python/eager/def_function.py", line 933, in _call
    self._initialize(args, kwds, add_initializers_to=initializers)
  File "/Users/ryukomura_laptop/.pyenv/versions/3.9.5/lib/python3.9/site-packages/tensorflow/python/eager/def_function.py", line 763, in _initialize
    self._stateful_fn._get_concrete_function_internal_garbage_collected(  # pylint: disable=protected-access
  File "/Users/ryukomura_laptop/.pyenv/versions/3.9.5/lib/python3.9/site-packages/tensorflow/python/eager/function.py", line 3050, in _get_concrete_function_internal_garbage_collected
    graph_function, _ = self._maybe_define_function(args, kwargs)
  File "/Users/ryukomura_laptop/.pyenv/versions/3.9.5/lib/python3.9/site-packages/tensorflow/python/eager/function.py", line 3444, in _maybe_define_function
    graph_function = self._create_graph_function(args, kwargs)
  File "/Users/ryukomura_laptop/.pyenv/versions/3.9.5/lib/python3.9/site-packages/tensorflow/python/eager/function.py", line 3279, in _create_graph_function
    func_graph_module.func_graph_from_py_func(
  File "/Users/ryukomura_laptop/.pyenv/versions/3.9.5/lib/python3.9/site-packages/tensorflow/python/framework/func_graph.py", line 999, in func_graph_from_py_func
    func_outputs = python_func(*func_args, **func_kwargs)
  File "/Users/ryukomura_laptop/.pyenv/versions/3.9.5/lib/python3.9/site-packages/tensorflow/python/eager/def_function.py", line 672, in wrapped_fn
    out = weak_wrapped_fn().__wrapped__(*args, **kwds)
  File "/Users/ryukomura_laptop/.pyenv/versions/3.9.5/lib/python3.9/site-packages/tensorflow/python/framework/func_graph.py", line 986, in wrapper
    raise e.ag_error_metadata.to_exception(e)
ValueError: in user code:

    /Users/ryukomura_laptop/.pyenv/versions/3.9.5/lib/python3.9/site-packages/keras/engine/training.py:1544 predict_function  *
        return step_function(self, iterator)
    /Users/ryukomura_laptop/.pyenv/versions/3.9.5/lib/python3.9/site-packages/keras/engine/training.py:1527 run_step  *
        outputs = model.predict_step(data)
    /Users/ryukomura_laptop/.pyenv/versions/3.9.5/lib/python3.9/site-packages/keras/engine/training.py:1500 predict_step  *
        return self(x, training=False)
    /Users/ryukomura_laptop/.pyenv/versions/3.9.5/lib/python3.9/site-packages/keras/engine/base_layer.py:989 __call__  *
        input_spec.assert_input_compatibility(self.input_spec, inputs, self.name)
    /Users/ryukomura_laptop/.pyenv/versions/3.9.5/lib/python3.9/site-packages/keras/engine/input_spec.py:248 assert_input_compatibility  *
        raise ValueError(

    ValueError: Input 0 of layer sequential is incompatible with the layer: expected axis -1 of input shape to have value 3 but received input with shape (None, 32, 32, 1)